<robot name="rosgolf_robot">

    <material name="orange">
        <color rgba="255 165 0 1"/>
    </material>

    <material name="yellow">
        <color rgba="255 255 0 1"/>
    </material>

    <material name="gray">
        <color rgba="128 128 128 1"/>
    </material>

    <material name="black">
        <color rgba="0 0 0 1"/>
    </material>

    <link name="base_link">
        <visual>
            <geometry>
                <box size="0.72 0.485 0.05"/>
            </geometry>
            <origin rpy="0 0 0" xyz="0.20 0 0.075"/>
            <material name="black"/>
        </visual>
        <collision>
            <geometry>
                <box size="0.72 0.70 0.40"/>
            </geometry>
            <origin rpy="0 0 0" xyz="0.20 0 0.20"/>
        </collision>
    </link>

<!--    <link name="base_footprint">-->
<!--        <visual>-->
<!--            <geometry>-->
<!--                <cylinder length="0.01" radius="0.12"/>-->
<!--            </geometry>-->
<!--            <origin rpy="0 0 0" xyz="0 0 0"/>-->
<!--            <material name="orange"/>-->
<!--        </visual>-->
<!--    </link>-->

<!--    <joint name="base_footprint_joint" type="fixed">-->
<!--        <parent link="base_footprint"/>-->
<!--        <child link="base_link"/>-->
<!--        <origin xyz="0 0 0" rpy="0 0 0"/>-->
<!--    </joint>-->

    <link name="cover">
        <visual>
            <geometry>
                <box size="0.72 0.485 0.15"/>
            </geometry>
            <origin rpy="0 0 0" xyz="0.20 0 0.175"/>
            <material name="yellow"/>
        </visual>
    </link>

    <joint name="base_to_cover" type="fixed">
        <parent link="base_link"/>
        <child link="cover"/>
        <origin xyz="0 0 0" rpy="0 0 0"/>
    </joint>

    <link name="lwheel">
        <visual>
            <geometry>
                <cylinder length="0.07" radius="0.12"/>
            </geometry>
            <origin rpy="0 0 0" xyz="0 0 0"/>
            <material name="black"/>
        </visual>
    </link>

    <joint name="left_wheel_hinge" type="continuous">
        <parent link="base_link"/>
        <child link="lwheel"/>
        <origin xyz="0 0.29 0.12" rpy="1.5708 0 0"/>
        <axis xyz="0 0 1"/>
    </joint>

    <link name="rwheel">
        <visual>
            <geometry>
                <cylinder length="0.07" radius="0.12"/>
            </geometry>
            <origin rpy="0 0 0" xyz="0 0 0"/>
            <material name="black"/>
        </visual>
    </link>

    <joint name="right_wheel_hinge" type="continuous">
        <parent link="base_link"/>
        <child link="rwheel"/>
        <origin xyz="0 -0.29 0.12" rpy="-1.5708 0 0"/>
        <axis xyz="0 0 1"/>
    </joint>

    <link name="fwheel">
        <visual>
            <geometry>
                <cylinder length="0.02" radius="0.035"/>
            </geometry>
            <origin rpy="1.578 0 0" xyz="0 0 0"/>
            <material name="gray"/>
        </visual>
    </link>

    <joint name="base_to_fwheel" type="fixed">
        <parent link="base_link"/>
        <child link="fwheel"/>
        <origin xyz="0.47 0 0.035" rpy="0 0 0"/>
    </joint>

    <link name="laser">
        <visual>
            <geometry>
                <cylinder length="0.04" radius="0.04"/>
            </geometry>
            <origin rpy="0 0 0" xyz="0 0 0"/>
            <material name="gray"/>
        </visual>
    </link>

    <joint name="base_to_scanner" type="fixed">
        <parent link="base_link"/>
        <child link="laser"/>
        <origin xyz="0.0 -0.04 0.26" rpy="0 0 0"/>
    </joint>

    <link name="camera_odom_frame" type="fixed">
        <geometry>
            <box size="0.11 0.015 0.025"/>
        </geometry>
    </link>

    <joint name="base_to_camera" type="fixed">
        <parent link="base_link"/>
        <child link="camera_odom_frame"/>
        <origin xyz="0.48 -0.045 0.145" rpy="0 0 0"/>
    </joint>

    <link name="sonar" type="fixed">
        <geometry>
            <box size="0.11 0.015 0.025"/>
        </geometry>
    </link>

    <joint name="base_to_sonar" type="fixed">
        <parent link="base_link"/>
        <child link="sonar"/>
        <origin xyz="0.48 0.0 0.145" rpy="0 0 0"/>
    </joint>

    <link name="imu" type="fixed">
        <geometry>
            <box size="0.11 0.015 0.025"/>
        </geometry>
    </link>

    <joint name="imu_to_sonar" type="fixed">
        <parent link="base_link"/>
        <child link="imu"/>
        <origin xyz="0.10 -0.10 0.18" rpy="0 0 0"/>
    </joint>

</robot>